<?xml version="1.0" ?>
<!-- =================================================================================== -->
<!-- |    This document was autogenerated by xacro from worms.xacro                    | -->
<!-- |    EDITING THIS FILE BY HAND IS NOT RECOMMENDED                                 | -->
<!-- =================================================================================== -->
<robot name="worms">
  <!-- <xacro:property name="thigh_offset_y" value="-0.0645" />
<xacro:property name="thigh_offset_z" value="-0.0145" /> -->
  <!-- TODO: Update component masses and inertias -->
  <!-- TODO: Add second ee, uib, and shoe -->
  <!-- TODO: Check link length specs -->
  <!-- TODO: Add simplified collision meshes -->
  <!-- Leg generation sub-macro -->
  <link name="base_link"/>
  <joint name="j_worms_attachment" type="fixed">
    <parent link="base_link"/>
    <child link="MP_BODY"/>
    <insert_block name="origin"/>
  </joint>
  <link name="MP_BODY">
    <inertial>
      <origin rpy="0 0 1.57" xyz="0 0 1.0"/>
      <mass value="7"/>
      <inertia ixx="0.003016" ixy="0.0" ixz="0.0" iyy="0.003016" iyz="0.0" izz="0.006014"/>
    </inertial>
    <visual>
      <origin rpy="0 0 1.57" xyz="0 0 1.0"/>
      <geometry>
        <!--box size="0.102 0.109 0.106" /-->
        <mesh filename="package://worms_description/meshes/pallet_reduced_new.stl" scale="1 1 1"/>
      </geometry>
      <material name="Red">
        <color rgba="0.2 0.2 0.2 1.0"/>
      </material>
    </visual>
    <!-- <collision>
          <origin xyz="0 0 ${initial_z_offset}" rpy="0 0 1.57" />
          <geometry>
            <mesh filename="package://worms_description/older_parts/pallet.stl"  scale="1 1 1"/>
          </geometry>

        </collision> -->
  </link>
  <gazebo reference="MP_BODY">
    <material>Gazebo/Red</material>
  </gazebo>
  <link name="hip_structure_rf">
    <inertial>
      <origin rpy="0 0 0" xyz="0 -0.15239999999999998 0"/>
      <mass value="1"/>
      <inertia ixx="0.0004167" ixy="0.0" ixz="0.0" iyy="0.0007417" iyz="0.0" izz="0.0007417"/>
    </inertial>
    <visual>
      <origin rpy="0 0 0" xyz="0 -0.15239999999999998 0"/>
      <geometry>
        <mesh filename="package://worms_description/meshes/hip_structure_reduced.stl" scale="1 1 1"/>
      </geometry>
      <material name="Grey">
        <color rgba="0.20 0.20 0.20 1.0"/>
      </material>
    </visual>
    <!-- <collision>
      <origin xyz="0 -${hip_structure_length + uib_ee_gap_length} 0" rpy="0 0 0"  />
      <geometry>
        <mesh filename="package://worms_description/meshes/hip_structure_reduced.stl"  scale="1 1 1"/>
      </geometry>
    </collision> -->
  </link>
  <link name="coxa_rf">
    <inertial>
      <origin rpy="0 0 0" xyz="0 0 0"/>
      <mass value="1.35"/>
      <inertia ixx="0.0004167" ixy="0.0" ixz="0.0" iyy="0.0007417" iyz="0.0" izz="0.0007417"/>
    </inertial>
    <visual>
      <origin rpy="0 0 0" xyz="0 0 0"/>
      <geometry>
        <mesh filename="package://worms_description/meshes/motor_coxa.stl" scale="1 1 1"/>
      </geometry>
      <material name="Grey">
        <color rgba="0.20 0.20 0.20 1.0"/>
      </material>
    </visual>
    <!-- <collision>
      <origin xyz="0 0 0" rpy="0 0 0"  />
      <geometry>
        <mesh filename="package://worms_description/meshes/motor_coxa.stl"  scale="1 1 1"/>
      </geometry>
    </collision> -->
  </link>
  <link name="thigh_rf">
    <inertial>
      <origin rpy="0 0 0" xyz="0 0 0"/>
      <mass value="2.85"/>
      <inertia ixx="0.0004167" ixy="0.0" ixz="0.0" iyy="0.0007417" iyz="0.0" izz="0.0007417"/>
    </inertial>
    <visual>
      <origin rpy="0 0 0" xyz="0 0 0"/>
      <geometry>
        <mesh filename="package://worms_description/meshes/motor_thigh.stl" scale="1 1 1"/>
      </geometry>
      <material name="Grey">
        <color rgba="0.20 0.20 0.20 1.0"/>
      </material>
    </visual>
    <!-- <collision>
      <origin xyz="0 0 0" rpy="0 0 0"  />
      <geometry>
        <mesh filename="package://worms_description/meshes/motor_thigh.stl"  scale="1 1 1"/>
      </geometry>
    </collision> -->
  </link>
  <link name="shin_rf">
    <inertial>
      <origin rpy="0 0 0" xyz="0 0 0"/>
      <mass value="6.85"/>
      <inertia ixx="0.0004167" ixy="0.0" ixz="0.0" iyy="0.0007417" iyz="0.0" izz="0.0007417"/>
    </inertial>
    <visual>
      <origin rpy="0 0 0" xyz="0 0 0"/>
      <geometry>
        <mesh filename="package://worms_description/meshes/motor_shin_ee_reduced.stl" scale="1 1 1"/>
      </geometry>
      <material name="Grey">
        <color rgba="0.20 0.20 0.20 1.0"/>
      </material>
    </visual>
    <!-- <collision>
      <origin xyz="0 0 0" rpy="0 0 0"  />
      <geometry>
        <mesh filename="package://worms_description/meshes/motor_shin_ee_reduced.stl"  scale="1 1 1"/>
      </geometry>
    </collision> -->
  </link>
  <link name="shoe_rf">
    <inertial>
      <origin rpy="0 0 0" xyz="0 0 0"/>
      <mass value="6.85"/>
      <inertia ixx="0.0004167" ixy="0.0" ixz="0.0" iyy="0.0007417" iyz="0.0" izz="0.29"/>
    </inertial>
    <visual>
      <origin rpy="0 0 0" xyz="0 0 0"/>
      <geometry>
        <mesh filename="package://worms_description/meshes/ee_shoe_reduced.stl" scale="1 1 1"/>
      </geometry>
      <material name="Grey">
        <color rgba="0.20 0.20 0.20 1.0"/>
      </material>
    </visual>
    <collision>
      <origin rpy="0 0 0" xyz="0 0 0"/>
      <geometry>
        <mesh filename="package://worms_description/meshes/ee_shoe_coll.stl" scale="1 1 1"/>
      </geometry>
    </collision>
  </link>
  <!-- Joint definitions -->
  <joint name="j_hip_structure_rf" type="fixed">
    <parent link="MP_BODY"/>
    <child link="hip_structure_rf"/>
    <origin rpy="0 0 1.05" xyz="0.476 -0.2748 1.0"/>
    <axis xyz="1 0 0"/>
    <limit effort="2.8" lower="-2.6179939" upper="2.6179939" velocity="5.6548668"/>
  </joint>
  <joint name="j_coxa_rf" type="revolute">
    <parent link="hip_structure_rf"/>
    <child link="coxa_rf"/>
    <origin rpy="0 0 0" xyz="0 -0.15239999999999998 0"/>
    <axis xyz="0 0 1"/>
    <limit effort="48" lower="-2.6179939" upper="2.6179939" velocity="5.6548668"/>
  </joint>
  <joint name="j_thigh_rf" type="revolute">
    <parent link="coxa_rf"/>
    <child link="thigh_rf"/>
    <origin rpy="0.785 0 0" xyz="0 -0.15 0"/>
    <axis xyz="1 0 0"/>
    <limit effort="48" lower="-2.6179939" upper="2.6179939" velocity="5.6548668"/>
  </joint>
  <joint name="j_shin_rf" type="revolute">
    <parent link="thigh_rf"/>
    <child link="shin_rf"/>
    <origin rpy="0.785 0 0" xyz="0 -0.27 0"/>
    <axis xyz="1 0 0"/>
    <limit effort="48" lower="-2.6179939" upper="2.6179939" velocity="5.6548668"/>
  </joint>
  <joint name="j_shoe_rf" type="fixed">
    <parent link="shin_rf"/>
    <child link="shoe_rf"/>
    <origin rpy="0 0 0" xyz="0 -0.5680000000000001 0"/>
    <axis xyz="1 0 0"/>
    <limit effort="48" lower="-2.6179939" upper="2.6179939" velocity="5.6548668"/>
  </joint>
  <!-- Joint transmission definitions -->
  <transmission name="t_coxa_rf">
    <type>transmission_interface/SimpleTransmission</type>
    <joint name="j_coxa_rf">
      <hardwareInterface>EffortJointInterface</hardwareInterface>
    </joint>
    <actuator name="m_coxa_rf">
      <hardwareInterface>EffortJointInterface</hardwareInterface>
      <mechanicalReduction>1</mechanicalReduction>
    </actuator>
  </transmission>
  <transmission name="t_thigh_rf">
    <type>transmission_interface/SimpleTransmission</type>
    <joint name="j_thigh_rf">
      <hardwareInterface>EffortJointInterface</hardwareInterface>
    </joint>
    <actuator name="m_thigh_rf">
      <hardwareInterface>EffortJointInterface</hardwareInterface>
      <mechanicalReduction>1</mechanicalReduction>
    </actuator>
  </transmission>
  <transmission name="t_shin_rf">
    <type>transmission_interface/SimpleTransmission</type>
    <joint name="j_shin_rf">
      <hardwareInterface>EffortJointInterface</hardwareInterface>
    </joint>
    <actuator name="m_shin_rf">
      <hardwareInterface>EffortJointInterface</hardwareInterface>
      <mechanicalReduction>1</mechanicalReduction>
    </actuator>
  </transmission>
  <!-- Gazebo material definitions -->
  <gazebo reference="hip_structure_rf">
    <material>Gazebo/Grey</material>
  </gazebo>
  <gazebo reference="coxa_rf">
    <material>Gazebo/Grey</material>
  </gazebo>
  <gazebo reference="thigh_rf">
    <material>Gazebo/Grey</material>
  </gazebo>
  <gazebo reference="shin_rf">
    <material>Gazebo/Grey</material>
  </gazebo>
  <gazebo reference="shoe_rf">
    <material>Gazebo/Grey</material>
  </gazebo>
  <!-- Gazebo gravity setting -->
  <!-- <turnGravityOff>1</turnGravityOff> -->
  <link name="hip_structure_rm">
    <inertial>
      <origin rpy="0 0 0" xyz="0 -0.15239999999999998 0"/>
      <mass value="1"/>
      <inertia ixx="0.0004167" ixy="0.0" ixz="0.0" iyy="0.0007417" iyz="0.0" izz="0.0007417"/>
    </inertial>
    <visual>
      <origin rpy="0 0 0" xyz="0 -0.15239999999999998 0"/>
      <geometry>
        <mesh filename="package://worms_description/meshes/hip_structure_reduced.stl" scale="1 1 1"/>
      </geometry>
      <material name="Grey">
        <color rgba="0.20 0.20 0.20 1.0"/>
      </material>
    </visual>
    <!-- <collision>
      <origin xyz="0 -${hip_structure_length + uib_ee_gap_length} 0" rpy="0 0 0"  />
      <geometry>
        <mesh filename="package://worms_description/meshes/hip_structure_reduced.stl"  scale="1 1 1"/>
      </geometry>
    </collision> -->
  </link>
  <link name="coxa_rm">
    <inertial>
      <origin rpy="0 0 0" xyz="0 0 0"/>
      <mass value="1.35"/>
      <inertia ixx="0.0004167" ixy="0.0" ixz="0.0" iyy="0.0007417" iyz="0.0" izz="0.0007417"/>
    </inertial>
    <visual>
      <origin rpy="0 0 0" xyz="0 0 0"/>
      <geometry>
        <mesh filename="package://worms_description/meshes/motor_coxa.stl" scale="1 1 1"/>
      </geometry>
      <material name="Grey">
        <color rgba="0.20 0.20 0.20 1.0"/>
      </material>
    </visual>
    <!-- <collision>
      <origin xyz="0 0 0" rpy="0 0 0"  />
      <geometry>
        <mesh filename="package://worms_description/meshes/motor_coxa.stl"  scale="1 1 1"/>
      </geometry>
    </collision> -->
  </link>
  <link name="thigh_rm">
    <inertial>
      <origin rpy="0 0 0" xyz="0 0 0"/>
      <mass value="2.85"/>
      <inertia ixx="0.0004167" ixy="0.0" ixz="0.0" iyy="0.0007417" iyz="0.0" izz="0.0007417"/>
    </inertial>
    <visual>
      <origin rpy="0 0 0" xyz="0 0 0"/>
      <geometry>
        <mesh filename="package://worms_description/meshes/motor_thigh.stl" scale="1 1 1"/>
      </geometry>
      <material name="Grey">
        <color rgba="0.20 0.20 0.20 1.0"/>
      </material>
    </visual>
    <!-- <collision>
      <origin xyz="0 0 0" rpy="0 0 0"  />
      <geometry>
        <mesh filename="package://worms_description/meshes/motor_thigh.stl"  scale="1 1 1"/>
      </geometry>
    </collision> -->
  </link>
  <link name="shin_rm">
    <inertial>
      <origin rpy="0 0 0" xyz="0 0 0"/>
      <mass value="6.85"/>
      <inertia ixx="0.0004167" ixy="0.0" ixz="0.0" iyy="0.0007417" iyz="0.0" izz="0.0007417"/>
    </inertial>
    <visual>
      <origin rpy="0 0 0" xyz="0 0 0"/>
      <geometry>
        <mesh filename="package://worms_description/meshes/motor_shin_ee_reduced.stl" scale="1 1 1"/>
      </geometry>
      <material name="Grey">
        <color rgba="0.20 0.20 0.20 1.0"/>
      </material>
    </visual>
    <!-- <collision>
      <origin xyz="0 0 0" rpy="0 0 0"  />
      <geometry>
        <mesh filename="package://worms_description/meshes/motor_shin_ee_reduced.stl"  scale="1 1 1"/>
      </geometry>
    </collision> -->
  </link>
  <link name="shoe_rm">
    <inertial>
      <origin rpy="0 0 0" xyz="0 0 0"/>
      <mass value="6.85"/>
      <inertia ixx="0.0004167" ixy="0.0" ixz="0.0" iyy="0.0007417" iyz="0.0" izz="0.29"/>
    </inertial>
    <visual>
      <origin rpy="0 0 0" xyz="0 0 0"/>
      <geometry>
        <mesh filename="package://worms_description/meshes/ee_shoe_reduced.stl" scale="1 1 1"/>
      </geometry>
      <material name="Grey">
        <color rgba="0.20 0.20 0.20 1.0"/>
      </material>
    </visual>
    <collision>
      <origin rpy="0 0 0" xyz="0 0 0"/>
      <geometry>
        <mesh filename="package://worms_description/meshes/ee_shoe_coll.stl" scale="1 1 1"/>
      </geometry>
    </collision>
  </link>
  <!-- Joint definitions -->
  <joint name="j_hip_structure_rm" type="fixed">
    <parent link="MP_BODY"/>
    <child link="hip_structure_rm"/>
    <origin rpy="0 0 0.0" xyz="0.0000 -0.5497 1.0"/>
    <axis xyz="1 0 0"/>
    <limit effort="2.8" lower="-2.6179939" upper="2.6179939" velocity="5.6548668"/>
  </joint>
  <joint name="j_coxa_rm" type="revolute">
    <parent link="hip_structure_rm"/>
    <child link="coxa_rm"/>
    <origin rpy="0 0 0" xyz="0 -0.15239999999999998 0"/>
    <axis xyz="0 0 1"/>
    <limit effort="48" lower="-2.6179939" upper="2.6179939" velocity="5.6548668"/>
  </joint>
  <joint name="j_thigh_rm" type="revolute">
    <parent link="coxa_rm"/>
    <child link="thigh_rm"/>
    <origin rpy="0.785 0 0" xyz="0 -0.15 0"/>
    <axis xyz="1 0 0"/>
    <limit effort="48" lower="-2.6179939" upper="2.6179939" velocity="5.6548668"/>
  </joint>
  <joint name="j_shin_rm" type="revolute">
    <parent link="thigh_rm"/>
    <child link="shin_rm"/>
    <origin rpy="0.785 0 0" xyz="0 -0.27 0"/>
    <axis xyz="1 0 0"/>
    <limit effort="48" lower="-2.6179939" upper="2.6179939" velocity="5.6548668"/>
  </joint>
  <joint name="j_shoe_rm" type="fixed">
    <parent link="shin_rm"/>
    <child link="shoe_rm"/>
    <origin rpy="0 0 0" xyz="0 -0.5680000000000001 0"/>
    <axis xyz="1 0 0"/>
    <limit effort="48" lower="-2.6179939" upper="2.6179939" velocity="5.6548668"/>
  </joint>
  <!-- Joint transmission definitions -->
  <transmission name="t_coxa_rm">
    <type>transmission_interface/SimpleTransmission</type>
    <joint name="j_coxa_rm">
      <hardwareInterface>EffortJointInterface</hardwareInterface>
    </joint>
    <actuator name="m_coxa_rm">
      <hardwareInterface>EffortJointInterface</hardwareInterface>
      <mechanicalReduction>1</mechanicalReduction>
    </actuator>
  </transmission>
  <transmission name="t_thigh_rm">
    <type>transmission_interface/SimpleTransmission</type>
    <joint name="j_thigh_rm">
      <hardwareInterface>EffortJointInterface</hardwareInterface>
    </joint>
    <actuator name="m_thigh_rm">
      <hardwareInterface>EffortJointInterface</hardwareInterface>
      <mechanicalReduction>1</mechanicalReduction>
    </actuator>
  </transmission>
  <transmission name="t_shin_rm">
    <type>transmission_interface/SimpleTransmission</type>
    <joint name="j_shin_rm">
      <hardwareInterface>EffortJointInterface</hardwareInterface>
    </joint>
    <actuator name="m_shin_rm">
      <hardwareInterface>EffortJointInterface</hardwareInterface>
      <mechanicalReduction>1</mechanicalReduction>
    </actuator>
  </transmission>
  <!-- Gazebo material definitions -->
  <gazebo reference="hip_structure_rm">
    <material>Gazebo/Grey</material>
  </gazebo>
  <gazebo reference="coxa_rm">
    <material>Gazebo/Grey</material>
  </gazebo>
  <gazebo reference="thigh_rm">
    <material>Gazebo/Grey</material>
  </gazebo>
  <gazebo reference="shin_rm">
    <material>Gazebo/Grey</material>
  </gazebo>
  <gazebo reference="shoe_rm">
    <material>Gazebo/Grey</material>
  </gazebo>
  <!-- Gazebo gravity setting -->
  <!-- <turnGravityOff>1</turnGravityOff> -->
  <link name="hip_structure_rr">
    <inertial>
      <origin rpy="0 0 0" xyz="0 -0.15239999999999998 0"/>
      <mass value="1"/>
      <inertia ixx="0.0004167" ixy="0.0" ixz="0.0" iyy="0.0007417" iyz="0.0" izz="0.0007417"/>
    </inertial>
    <visual>
      <origin rpy="0 0 0" xyz="0 -0.15239999999999998 0"/>
      <geometry>
        <mesh filename="package://worms_description/meshes/hip_structure_reduced.stl" scale="1 1 1"/>
      </geometry>
      <material name="Grey">
        <color rgba="0.20 0.20 0.20 1.0"/>
      </material>
    </visual>
    <!-- <collision>
      <origin xyz="0 -${hip_structure_length + uib_ee_gap_length} 0" rpy="0 0 0"  />
      <geometry>
        <mesh filename="package://worms_description/meshes/hip_structure_reduced.stl"  scale="1 1 1"/>
      </geometry>
    </collision> -->
  </link>
  <link name="coxa_rr">
    <inertial>
      <origin rpy="0 0 0" xyz="0 0 0"/>
      <mass value="1.35"/>
      <inertia ixx="0.0004167" ixy="0.0" ixz="0.0" iyy="0.0007417" iyz="0.0" izz="0.0007417"/>
    </inertial>
    <visual>
      <origin rpy="0 0 0" xyz="0 0 0"/>
      <geometry>
        <mesh filename="package://worms_description/meshes/motor_coxa.stl" scale="1 1 1"/>
      </geometry>
      <material name="Grey">
        <color rgba="0.20 0.20 0.20 1.0"/>
      </material>
    </visual>
    <!-- <collision>
      <origin xyz="0 0 0" rpy="0 0 0"  />
      <geometry>
        <mesh filename="package://worms_description/meshes/motor_coxa.stl"  scale="1 1 1"/>
      </geometry>
    </collision> -->
  </link>
  <link name="thigh_rr">
    <inertial>
      <origin rpy="0 0 0" xyz="0 0 0"/>
      <mass value="2.85"/>
      <inertia ixx="0.0004167" ixy="0.0" ixz="0.0" iyy="0.0007417" iyz="0.0" izz="0.0007417"/>
    </inertial>
    <visual>
      <origin rpy="0 0 0" xyz="0 0 0"/>
      <geometry>
        <mesh filename="package://worms_description/meshes/motor_thigh.stl" scale="1 1 1"/>
      </geometry>
      <material name="Grey">
        <color rgba="0.20 0.20 0.20 1.0"/>
      </material>
    </visual>
    <!-- <collision>
      <origin xyz="0 0 0" rpy="0 0 0"  />
      <geometry>
        <mesh filename="package://worms_description/meshes/motor_thigh.stl"  scale="1 1 1"/>
      </geometry>
    </collision> -->
  </link>
  <link name="shin_rr">
    <inertial>
      <origin rpy="0 0 0" xyz="0 0 0"/>
      <mass value="6.85"/>
      <inertia ixx="0.0004167" ixy="0.0" ixz="0.0" iyy="0.0007417" iyz="0.0" izz="0.0007417"/>
    </inertial>
    <visual>
      <origin rpy="0 0 0" xyz="0 0 0"/>
      <geometry>
        <mesh filename="package://worms_description/meshes/motor_shin_ee_reduced.stl" scale="1 1 1"/>
      </geometry>
      <material name="Grey">
        <color rgba="0.20 0.20 0.20 1.0"/>
      </material>
    </visual>
    <!-- <collision>
      <origin xyz="0 0 0" rpy="0 0 0"  />
      <geometry>
        <mesh filename="package://worms_description/meshes/motor_shin_ee_reduced.stl"  scale="1 1 1"/>
      </geometry>
    </collision> -->
  </link>
  <link name="shoe_rr">
    <inertial>
      <origin rpy="0 0 0" xyz="0 0 0"/>
      <mass value="6.85"/>
      <inertia ixx="0.0004167" ixy="0.0" ixz="0.0" iyy="0.0007417" iyz="0.0" izz="0.29"/>
    </inertial>
    <visual>
      <origin rpy="0 0 0" xyz="0 0 0"/>
      <geometry>
        <mesh filename="package://worms_description/meshes/ee_shoe_reduced.stl" scale="1 1 1"/>
      </geometry>
      <material name="Grey">
        <color rgba="0.20 0.20 0.20 1.0"/>
      </material>
    </visual>
    <collision>
      <origin rpy="0 0 0" xyz="0 0 0"/>
      <geometry>
        <mesh filename="package://worms_description/meshes/ee_shoe_coll.stl" scale="1 1 1"/>
      </geometry>
    </collision>
  </link>
  <!-- Joint definitions -->
  <joint name="j_hip_structure_rr" type="fixed">
    <parent link="MP_BODY"/>
    <child link="hip_structure_rr"/>
    <origin rpy="0 0 -1.0400000000000003" xyz="-0.476 -0.2748 1.0"/>
    <axis xyz="1 0 0"/>
    <limit effort="2.8" lower="-2.6179939" upper="2.6179939" velocity="5.6548668"/>
  </joint>
  <joint name="j_coxa_rr" type="revolute">
    <parent link="hip_structure_rr"/>
    <child link="coxa_rr"/>
    <origin rpy="0 0 0" xyz="0 -0.15239999999999998 0"/>
    <axis xyz="0 0 1"/>
    <limit effort="48" lower="-2.6179939" upper="2.6179939" velocity="5.6548668"/>
  </joint>
  <joint name="j_thigh_rr" type="revolute">
    <parent link="coxa_rr"/>
    <child link="thigh_rr"/>
    <origin rpy="0.785 0 0" xyz="0 -0.15 0"/>
    <axis xyz="1 0 0"/>
    <limit effort="48" lower="-2.6179939" upper="2.6179939" velocity="5.6548668"/>
  </joint>
  <joint name="j_shin_rr" type="revolute">
    <parent link="thigh_rr"/>
    <child link="shin_rr"/>
    <origin rpy="0.785 0 0" xyz="0 -0.27 0"/>
    <axis xyz="1 0 0"/>
    <limit effort="48" lower="-2.6179939" upper="2.6179939" velocity="5.6548668"/>
  </joint>
  <joint name="j_shoe_rr" type="fixed">
    <parent link="shin_rr"/>
    <child link="shoe_rr"/>
    <origin rpy="0 0 0" xyz="0 -0.5680000000000001 0"/>
    <axis xyz="1 0 0"/>
    <limit effort="48" lower="-2.6179939" upper="2.6179939" velocity="5.6548668"/>
  </joint>
  <!-- Joint transmission definitions -->
  <transmission name="t_coxa_rr">
    <type>transmission_interface/SimpleTransmission</type>
    <joint name="j_coxa_rr">
      <hardwareInterface>EffortJointInterface</hardwareInterface>
    </joint>
    <actuator name="m_coxa_rr">
      <hardwareInterface>EffortJointInterface</hardwareInterface>
      <mechanicalReduction>1</mechanicalReduction>
    </actuator>
  </transmission>
  <transmission name="t_thigh_rr">
    <type>transmission_interface/SimpleTransmission</type>
    <joint name="j_thigh_rr">
      <hardwareInterface>EffortJointInterface</hardwareInterface>
    </joint>
    <actuator name="m_thigh_rr">
      <hardwareInterface>EffortJointInterface</hardwareInterface>
      <mechanicalReduction>1</mechanicalReduction>
    </actuator>
  </transmission>
  <transmission name="t_shin_rr">
    <type>transmission_interface/SimpleTransmission</type>
    <joint name="j_shin_rr">
      <hardwareInterface>EffortJointInterface</hardwareInterface>
    </joint>
    <actuator name="m_shin_rr">
      <hardwareInterface>EffortJointInterface</hardwareInterface>
      <mechanicalReduction>1</mechanicalReduction>
    </actuator>
  </transmission>
  <!-- Gazebo material definitions -->
  <gazebo reference="hip_structure_rr">
    <material>Gazebo/Grey</material>
  </gazebo>
  <gazebo reference="coxa_rr">
    <material>Gazebo/Grey</material>
  </gazebo>
  <gazebo reference="thigh_rr">
    <material>Gazebo/Grey</material>
  </gazebo>
  <gazebo reference="shin_rr">
    <material>Gazebo/Grey</material>
  </gazebo>
  <gazebo reference="shoe_rr">
    <material>Gazebo/Grey</material>
  </gazebo>
  <!-- Gazebo gravity setting -->
  <!-- <turnGravityOff>1</turnGravityOff> -->
  <link name="hip_structure_lf">
    <inertial>
      <origin rpy="0 0 0" xyz="0 -0.15239999999999998 0"/>
      <mass value="1"/>
      <inertia ixx="0.0004167" ixy="0.0" ixz="0.0" iyy="0.0007417" iyz="0.0" izz="0.0007417"/>
    </inertial>
    <visual>
      <origin rpy="0 0 0" xyz="0 -0.15239999999999998 0"/>
      <geometry>
        <mesh filename="package://worms_description/meshes/hip_structure_reduced.stl" scale="1 1 1"/>
      </geometry>
      <material name="Grey">
        <color rgba="0.20 0.20 0.20 1.0"/>
      </material>
    </visual>
    <!-- <collision>
      <origin xyz="0 -${hip_structure_length + uib_ee_gap_length} 0" rpy="0 0 0"  />
      <geometry>
        <mesh filename="package://worms_description/meshes/hip_structure_reduced.stl"  scale="1 1 1"/>
      </geometry>
    </collision> -->
  </link>
  <link name="coxa_lf">
    <inertial>
      <origin rpy="0 0 0" xyz="0 0 0"/>
      <mass value="1.35"/>
      <inertia ixx="0.0004167" ixy="0.0" ixz="0.0" iyy="0.0007417" iyz="0.0" izz="0.0007417"/>
    </inertial>
    <visual>
      <origin rpy="0 0 0" xyz="0 0 0"/>
      <geometry>
        <mesh filename="package://worms_description/meshes/motor_coxa.stl" scale="1 1 1"/>
      </geometry>
      <material name="Grey">
        <color rgba="0.20 0.20 0.20 1.0"/>
      </material>
    </visual>
    <!-- <collision>
      <origin xyz="0 0 0" rpy="0 0 0"  />
      <geometry>
        <mesh filename="package://worms_description/meshes/motor_coxa.stl"  scale="1 1 1"/>
      </geometry>
    </collision> -->
  </link>
  <link name="thigh_lf">
    <inertial>
      <origin rpy="0 0 0" xyz="0 0 0"/>
      <mass value="2.85"/>
      <inertia ixx="0.0004167" ixy="0.0" ixz="0.0" iyy="0.0007417" iyz="0.0" izz="0.0007417"/>
    </inertial>
    <visual>
      <origin rpy="0 0 0" xyz="0 0 0"/>
      <geometry>
        <mesh filename="package://worms_description/meshes/motor_thigh.stl" scale="1 1 1"/>
      </geometry>
      <material name="Grey">
        <color rgba="0.20 0.20 0.20 1.0"/>
      </material>
    </visual>
    <!-- <collision>
      <origin xyz="0 0 0" rpy="0 0 0"  />
      <geometry>
        <mesh filename="package://worms_description/meshes/motor_thigh.stl"  scale="1 1 1"/>
      </geometry>
    </collision> -->
  </link>
  <link name="shin_lf">
    <inertial>
      <origin rpy="0 0 0" xyz="0 0 0"/>
      <mass value="6.85"/>
      <inertia ixx="0.0004167" ixy="0.0" ixz="0.0" iyy="0.0007417" iyz="0.0" izz="0.0007417"/>
    </inertial>
    <visual>
      <origin rpy="0 0 0" xyz="0 0 0"/>
      <geometry>
        <mesh filename="package://worms_description/meshes/motor_shin_ee_reduced.stl" scale="1 1 1"/>
      </geometry>
      <material name="Grey">
        <color rgba="0.20 0.20 0.20 1.0"/>
      </material>
    </visual>
    <!-- <collision>
      <origin xyz="0 0 0" rpy="0 0 0"  />
      <geometry>
        <mesh filename="package://worms_description/meshes/motor_shin_ee_reduced.stl"  scale="1 1 1"/>
      </geometry>
    </collision> -->
  </link>
  <link name="shoe_lf">
    <inertial>
      <origin rpy="0 0 0" xyz="0 0 0"/>
      <mass value="6.85"/>
      <inertia ixx="0.0004167" ixy="0.0" ixz="0.0" iyy="0.0007417" iyz="0.0" izz="0.29"/>
    </inertial>
    <visual>
      <origin rpy="0 0 0" xyz="0 0 0"/>
      <geometry>
        <mesh filename="package://worms_description/meshes/ee_shoe_reduced.stl" scale="1 1 1"/>
      </geometry>
      <material name="Grey">
        <color rgba="0.20 0.20 0.20 1.0"/>
      </material>
    </visual>
    <collision>
      <origin rpy="0 0 0" xyz="0 0 0"/>
      <geometry>
        <mesh filename="package://worms_description/meshes/ee_shoe_coll.stl" scale="1 1 1"/>
      </geometry>
    </collision>
  </link>
  <!-- Joint definitions -->
  <joint name="j_hip_structure_lf" type="fixed">
    <parent link="MP_BODY"/>
    <child link="hip_structure_lf"/>
    <origin rpy="0 0 2.09" xyz="0.476 0.2748 1.0"/>
    <axis xyz="1 0 0"/>
    <limit effort="2.8" lower="-2.6179939" upper="2.6179939" velocity="5.6548668"/>
  </joint>
  <joint name="j_coxa_lf" type="revolute">
    <parent link="hip_structure_lf"/>
    <child link="coxa_lf"/>
    <origin rpy="0 0 0" xyz="0 -0.15239999999999998 0"/>
    <axis xyz="0 0 1"/>
    <limit effort="48" lower="-2.6179939" upper="2.6179939" velocity="5.6548668"/>
  </joint>
  <joint name="j_thigh_lf" type="revolute">
    <parent link="coxa_lf"/>
    <child link="thigh_lf"/>
    <origin rpy="0.785 0 0" xyz="0 -0.15 0"/>
    <axis xyz="1 0 0"/>
    <limit effort="48" lower="-2.6179939" upper="2.6179939" velocity="5.6548668"/>
  </joint>
  <joint name="j_shin_lf" type="revolute">
    <parent link="thigh_lf"/>
    <child link="shin_lf"/>
    <origin rpy="0.785 0 0" xyz="0 -0.27 0"/>
    <axis xyz="1 0 0"/>
    <limit effort="48" lower="-2.6179939" upper="2.6179939" velocity="5.6548668"/>
  </joint>
  <joint name="j_shoe_lf" type="fixed">
    <parent link="shin_lf"/>
    <child link="shoe_lf"/>
    <origin rpy="0 0 0" xyz="0 -0.5680000000000001 0"/>
    <axis xyz="1 0 0"/>
    <limit effort="48" lower="-2.6179939" upper="2.6179939" velocity="5.6548668"/>
  </joint>
  <!-- Joint transmission definitions -->
  <transmission name="t_coxa_lf">
    <type>transmission_interface/SimpleTransmission</type>
    <joint name="j_coxa_lf">
      <hardwareInterface>EffortJointInterface</hardwareInterface>
    </joint>
    <actuator name="m_coxa_lf">
      <hardwareInterface>EffortJointInterface</hardwareInterface>
      <mechanicalReduction>1</mechanicalReduction>
    </actuator>
  </transmission>
  <transmission name="t_thigh_lf">
    <type>transmission_interface/SimpleTransmission</type>
    <joint name="j_thigh_lf">
      <hardwareInterface>EffortJointInterface</hardwareInterface>
    </joint>
    <actuator name="m_thigh_lf">
      <hardwareInterface>EffortJointInterface</hardwareInterface>
      <mechanicalReduction>1</mechanicalReduction>
    </actuator>
  </transmission>
  <transmission name="t_shin_lf">
    <type>transmission_interface/SimpleTransmission</type>
    <joint name="j_shin_lf">
      <hardwareInterface>EffortJointInterface</hardwareInterface>
    </joint>
    <actuator name="m_shin_lf">
      <hardwareInterface>EffortJointInterface</hardwareInterface>
      <mechanicalReduction>1</mechanicalReduction>
    </actuator>
  </transmission>
  <!-- Gazebo material definitions -->
  <gazebo reference="hip_structure_lf">
    <material>Gazebo/Grey</material>
  </gazebo>
  <gazebo reference="coxa_lf">
    <material>Gazebo/Grey</material>
  </gazebo>
  <gazebo reference="thigh_lf">
    <material>Gazebo/Grey</material>
  </gazebo>
  <gazebo reference="shin_lf">
    <material>Gazebo/Grey</material>
  </gazebo>
  <gazebo reference="shoe_lf">
    <material>Gazebo/Grey</material>
  </gazebo>
  <!-- Gazebo gravity setting -->
  <!-- <turnGravityOff>1</turnGravityOff> -->
  <link name="hip_structure_lm">
    <inertial>
      <origin rpy="0 0 0" xyz="0 -0.15239999999999998 0"/>
      <mass value="1"/>
      <inertia ixx="0.0004167" ixy="0.0" ixz="0.0" iyy="0.0007417" iyz="0.0" izz="0.0007417"/>
    </inertial>
    <visual>
      <origin rpy="0 0 0" xyz="0 -0.15239999999999998 0"/>
      <geometry>
        <mesh filename="package://worms_description/meshes/hip_structure_reduced.stl" scale="1 1 1"/>
      </geometry>
      <material name="Grey">
        <color rgba="0.20 0.20 0.20 1.0"/>
      </material>
    </visual>
    <!-- <collision>
      <origin xyz="0 -${hip_structure_length + uib_ee_gap_length} 0" rpy="0 0 0"  />
      <geometry>
        <mesh filename="package://worms_description/meshes/hip_structure_reduced.stl"  scale="1 1 1"/>
      </geometry>
    </collision> -->
  </link>
  <link name="coxa_lm">
    <inertial>
      <origin rpy="0 0 0" xyz="0 0 0"/>
      <mass value="1.35"/>
      <inertia ixx="0.0004167" ixy="0.0" ixz="0.0" iyy="0.0007417" iyz="0.0" izz="0.0007417"/>
    </inertial>
    <visual>
      <origin rpy="0 0 0" xyz="0 0 0"/>
      <geometry>
        <mesh filename="package://worms_description/meshes/motor_coxa.stl" scale="1 1 1"/>
      </geometry>
      <material name="Grey">
        <color rgba="0.20 0.20 0.20 1.0"/>
      </material>
    </visual>
    <!-- <collision>
      <origin xyz="0 0 0" rpy="0 0 0"  />
      <geometry>
        <mesh filename="package://worms_description/meshes/motor_coxa.stl"  scale="1 1 1"/>
      </geometry>
    </collision> -->
  </link>
  <link name="thigh_lm">
    <inertial>
      <origin rpy="0 0 0" xyz="0 0 0"/>
      <mass value="2.85"/>
      <inertia ixx="0.0004167" ixy="0.0" ixz="0.0" iyy="0.0007417" iyz="0.0" izz="0.0007417"/>
    </inertial>
    <visual>
      <origin rpy="0 0 0" xyz="0 0 0"/>
      <geometry>
        <mesh filename="package://worms_description/meshes/motor_thigh.stl" scale="1 1 1"/>
      </geometry>
      <material name="Grey">
        <color rgba="0.20 0.20 0.20 1.0"/>
      </material>
    </visual>
    <!-- <collision>
      <origin xyz="0 0 0" rpy="0 0 0"  />
      <geometry>
        <mesh filename="package://worms_description/meshes/motor_thigh.stl"  scale="1 1 1"/>
      </geometry>
    </collision> -->
  </link>
  <link name="shin_lm">
    <inertial>
      <origin rpy="0 0 0" xyz="0 0 0"/>
      <mass value="6.85"/>
      <inertia ixx="0.0004167" ixy="0.0" ixz="0.0" iyy="0.0007417" iyz="0.0" izz="0.0007417"/>
    </inertial>
    <visual>
      <origin rpy="0 0 0" xyz="0 0 0"/>
      <geometry>
        <mesh filename="package://worms_description/meshes/motor_shin_ee_reduced.stl" scale="1 1 1"/>
      </geometry>
      <material name="Grey">
        <color rgba="0.20 0.20 0.20 1.0"/>
      </material>
    </visual>
    <!-- <collision>
      <origin xyz="0 0 0" rpy="0 0 0"  />
      <geometry>
        <mesh filename="package://worms_description/meshes/motor_shin_ee_reduced.stl"  scale="1 1 1"/>
      </geometry>
    </collision> -->
  </link>
  <link name="shoe_lm">
    <inertial>
      <origin rpy="0 0 0" xyz="0 0 0"/>
      <mass value="6.85"/>
      <inertia ixx="0.0004167" ixy="0.0" ixz="0.0" iyy="0.0007417" iyz="0.0" izz="0.29"/>
    </inertial>
    <visual>
      <origin rpy="0 0 0" xyz="0 0 0"/>
      <geometry>
        <mesh filename="package://worms_description/meshes/ee_shoe_reduced.stl" scale="1 1 1"/>
      </geometry>
      <material name="Grey">
        <color rgba="0.20 0.20 0.20 1.0"/>
      </material>
    </visual>
    <collision>
      <origin rpy="0 0 0" xyz="0 0 0"/>
      <geometry>
        <mesh filename="package://worms_description/meshes/ee_shoe_coll.stl" scale="1 1 1"/>
      </geometry>
    </collision>
  </link>
  <!-- Joint definitions -->
  <joint name="j_hip_structure_lm" type="fixed">
    <parent link="MP_BODY"/>
    <child link="hip_structure_lm"/>
    <origin rpy="0 0 3.14" xyz="0.0000 0.5497 1.0"/>
    <axis xyz="1 0 0"/>
    <limit effort="2.8" lower="-2.6179939" upper="2.6179939" velocity="5.6548668"/>
  </joint>
  <joint name="j_coxa_lm" type="revolute">
    <parent link="hip_structure_lm"/>
    <child link="coxa_lm"/>
    <origin rpy="0 0 0" xyz="0 -0.15239999999999998 0"/>
    <axis xyz="0 0 1"/>
    <limit effort="48" lower="-2.6179939" upper="2.6179939" velocity="5.6548668"/>
  </joint>
  <joint name="j_thigh_lm" type="revolute">
    <parent link="coxa_lm"/>
    <child link="thigh_lm"/>
    <origin rpy="0.785 0 0" xyz="0 -0.15 0"/>
    <axis xyz="1 0 0"/>
    <limit effort="48" lower="-2.6179939" upper="2.6179939" velocity="5.6548668"/>
  </joint>
  <joint name="j_shin_lm" type="revolute">
    <parent link="thigh_lm"/>
    <child link="shin_lm"/>
    <origin rpy="0.785 0 0" xyz="0 -0.27 0"/>
    <axis xyz="1 0 0"/>
    <limit effort="48" lower="-2.6179939" upper="2.6179939" velocity="5.6548668"/>
  </joint>
  <joint name="j_shoe_lm" type="fixed">
    <parent link="shin_lm"/>
    <child link="shoe_lm"/>
    <origin rpy="0 0 0" xyz="0 -0.5680000000000001 0"/>
    <axis xyz="1 0 0"/>
    <limit effort="48" lower="-2.6179939" upper="2.6179939" velocity="5.6548668"/>
  </joint>
  <!-- Joint transmission definitions -->
  <transmission name="t_coxa_lm">
    <type>transmission_interface/SimpleTransmission</type>
    <joint name="j_coxa_lm">
      <hardwareInterface>EffortJointInterface</hardwareInterface>
    </joint>
    <actuator name="m_coxa_lm">
      <hardwareInterface>EffortJointInterface</hardwareInterface>
      <mechanicalReduction>1</mechanicalReduction>
    </actuator>
  </transmission>
  <transmission name="t_thigh_lm">
    <type>transmission_interface/SimpleTransmission</type>
    <joint name="j_thigh_lm">
      <hardwareInterface>EffortJointInterface</hardwareInterface>
    </joint>
    <actuator name="m_thigh_lm">
      <hardwareInterface>EffortJointInterface</hardwareInterface>
      <mechanicalReduction>1</mechanicalReduction>
    </actuator>
  </transmission>
  <transmission name="t_shin_lm">
    <type>transmission_interface/SimpleTransmission</type>
    <joint name="j_shin_lm">
      <hardwareInterface>EffortJointInterface</hardwareInterface>
    </joint>
    <actuator name="m_shin_lm">
      <hardwareInterface>EffortJointInterface</hardwareInterface>
      <mechanicalReduction>1</mechanicalReduction>
    </actuator>
  </transmission>
  <!-- Gazebo material definitions -->
  <gazebo reference="hip_structure_lm">
    <material>Gazebo/Grey</material>
  </gazebo>
  <gazebo reference="coxa_lm">
    <material>Gazebo/Grey</material>
  </gazebo>
  <gazebo reference="thigh_lm">
    <material>Gazebo/Grey</material>
  </gazebo>
  <gazebo reference="shin_lm">
    <material>Gazebo/Grey</material>
  </gazebo>
  <gazebo reference="shoe_lm">
    <material>Gazebo/Grey</material>
  </gazebo>
  <!-- Gazebo gravity setting -->
  <!-- <turnGravityOff>1</turnGravityOff> -->
  <link name="hip_structure_lr">
    <inertial>
      <origin rpy="0 0 0" xyz="0 -0.15239999999999998 0"/>
      <mass value="1"/>
      <inertia ixx="0.0004167" ixy="0.0" ixz="0.0" iyy="0.0007417" iyz="0.0" izz="0.0007417"/>
    </inertial>
    <visual>
      <origin rpy="0 0 0" xyz="0 -0.15239999999999998 0"/>
      <geometry>
        <mesh filename="package://worms_description/meshes/hip_structure_reduced.stl" scale="1 1 1"/>
      </geometry>
      <material name="Grey">
        <color rgba="0.20 0.20 0.20 1.0"/>
      </material>
    </visual>
    <!-- <collision>
      <origin xyz="0 -${hip_structure_length + uib_ee_gap_length} 0" rpy="0 0 0"  />
      <geometry>
        <mesh filename="package://worms_description/meshes/hip_structure_reduced.stl"  scale="1 1 1"/>
      </geometry>
    </collision> -->
  </link>
  <link name="coxa_lr">
    <inertial>
      <origin rpy="0 0 0" xyz="0 0 0"/>
      <mass value="1.35"/>
      <inertia ixx="0.0004167" ixy="0.0" ixz="0.0" iyy="0.0007417" iyz="0.0" izz="0.0007417"/>
    </inertial>
    <visual>
      <origin rpy="0 0 0" xyz="0 0 0"/>
      <geometry>
        <mesh filename="package://worms_description/meshes/motor_coxa.stl" scale="1 1 1"/>
      </geometry>
      <material name="Grey">
        <color rgba="0.20 0.20 0.20 1.0"/>
      </material>
    </visual>
    <!-- <collision>
      <origin xyz="0 0 0" rpy="0 0 0"  />
      <geometry>
        <mesh filename="package://worms_description/meshes/motor_coxa.stl"  scale="1 1 1"/>
      </geometry>
    </collision> -->
  </link>
  <link name="thigh_lr">
    <inertial>
      <origin rpy="0 0 0" xyz="0 0 0"/>
      <mass value="2.85"/>
      <inertia ixx="0.0004167" ixy="0.0" ixz="0.0" iyy="0.0007417" iyz="0.0" izz="0.0007417"/>
    </inertial>
    <visual>
      <origin rpy="0 0 0" xyz="0 0 0"/>
      <geometry>
        <mesh filename="package://worms_description/meshes/motor_thigh.stl" scale="1 1 1"/>
      </geometry>
      <material name="Grey">
        <color rgba="0.20 0.20 0.20 1.0"/>
      </material>
    </visual>
    <!-- <collision>
      <origin xyz="0 0 0" rpy="0 0 0"  />
      <geometry>
        <mesh filename="package://worms_description/meshes/motor_thigh.stl"  scale="1 1 1"/>
      </geometry>
    </collision> -->
  </link>
  <link name="shin_lr">
    <inertial>
      <origin rpy="0 0 0" xyz="0 0 0"/>
      <mass value="6.85"/>
      <inertia ixx="0.0004167" ixy="0.0" ixz="0.0" iyy="0.0007417" iyz="0.0" izz="0.0007417"/>
    </inertial>
    <visual>
      <origin rpy="0 0 0" xyz="0 0 0"/>
      <geometry>
        <mesh filename="package://worms_description/meshes/motor_shin_ee_reduced.stl" scale="1 1 1"/>
      </geometry>
      <material name="Grey">
        <color rgba="0.20 0.20 0.20 1.0"/>
      </material>
    </visual>
    <!-- <collision>
      <origin xyz="0 0 0" rpy="0 0 0"  />
      <geometry>
        <mesh filename="package://worms_description/meshes/motor_shin_ee_reduced.stl"  scale="1 1 1"/>
      </geometry>
    </collision> -->
  </link>
  <link name="shoe_lr">
    <inertial>
      <origin rpy="0 0 0" xyz="0 0 0"/>
      <mass value="6.85"/>
      <inertia ixx="0.0004167" ixy="0.0" ixz="0.0" iyy="0.0007417" iyz="0.0" izz="0.29"/>
    </inertial>
    <visual>
      <origin rpy="0 0 0" xyz="0 0 0"/>
      <geometry>
        <mesh filename="package://worms_description/meshes/ee_shoe_reduced.stl" scale="1 1 1"/>
      </geometry>
      <material name="Grey">
        <color rgba="0.20 0.20 0.20 1.0"/>
      </material>
    </visual>
    <collision>
      <origin rpy="0 0 0" xyz="0 0 0"/>
      <geometry>
        <mesh filename="package://worms_description/meshes/ee_shoe_coll.stl" scale="1 1 1"/>
      </geometry>
    </collision>
  </link>
  <!-- Joint definitions -->
  <joint name="j_hip_structure_lr" type="fixed">
    <parent link="MP_BODY"/>
    <child link="hip_structure_lr"/>
    <origin rpy="0 0 4.180000000000001" xyz="-0.476 0.2748 1.0"/>
    <axis xyz="1 0 0"/>
    <limit effort="2.8" lower="-2.6179939" upper="2.6179939" velocity="5.6548668"/>
  </joint>
  <joint name="j_coxa_lr" type="revolute">
    <parent link="hip_structure_lr"/>
    <child link="coxa_lr"/>
    <origin rpy="0 0 0" xyz="0 -0.15239999999999998 0"/>
    <axis xyz="0 0 1"/>
    <limit effort="48" lower="-2.6179939" upper="2.6179939" velocity="5.6548668"/>
  </joint>
  <joint name="j_thigh_lr" type="revolute">
    <parent link="coxa_lr"/>
    <child link="thigh_lr"/>
    <origin rpy="0.785 0 0" xyz="0 -0.15 0"/>
    <axis xyz="1 0 0"/>
    <limit effort="48" lower="-2.6179939" upper="2.6179939" velocity="5.6548668"/>
  </joint>
  <joint name="j_shin_lr" type="revolute">
    <parent link="thigh_lr"/>
    <child link="shin_lr"/>
    <origin rpy="0.785 0 0" xyz="0 -0.27 0"/>
    <axis xyz="1 0 0"/>
    <limit effort="48" lower="-2.6179939" upper="2.6179939" velocity="5.6548668"/>
  </joint>
  <joint name="j_shoe_lr" type="fixed">
    <parent link="shin_lr"/>
    <child link="shoe_lr"/>
    <origin rpy="0 0 0" xyz="0 -0.5680000000000001 0"/>
    <axis xyz="1 0 0"/>
    <limit effort="48" lower="-2.6179939" upper="2.6179939" velocity="5.6548668"/>
  </joint>
  <!-- Joint transmission definitions -->
  <transmission name="t_coxa_lr">
    <type>transmission_interface/SimpleTransmission</type>
    <joint name="j_coxa_lr">
      <hardwareInterface>EffortJointInterface</hardwareInterface>
    </joint>
    <actuator name="m_coxa_lr">
      <hardwareInterface>EffortJointInterface</hardwareInterface>
      <mechanicalReduction>1</mechanicalReduction>
    </actuator>
  </transmission>
  <transmission name="t_thigh_lr">
    <type>transmission_interface/SimpleTransmission</type>
    <joint name="j_thigh_lr">
      <hardwareInterface>EffortJointInterface</hardwareInterface>
    </joint>
    <actuator name="m_thigh_lr">
      <hardwareInterface>EffortJointInterface</hardwareInterface>
      <mechanicalReduction>1</mechanicalReduction>
    </actuator>
  </transmission>
  <transmission name="t_shin_lr">
    <type>transmission_interface/SimpleTransmission</type>
    <joint name="j_shin_lr">
      <hardwareInterface>EffortJointInterface</hardwareInterface>
    </joint>
    <actuator name="m_shin_lr">
      <hardwareInterface>EffortJointInterface</hardwareInterface>
      <mechanicalReduction>1</mechanicalReduction>
    </actuator>
  </transmission>
  <!-- Gazebo material definitions -->
  <gazebo reference="hip_structure_lr">
    <material>Gazebo/Grey</material>
  </gazebo>
  <gazebo reference="coxa_lr">
    <material>Gazebo/Grey</material>
  </gazebo>
  <gazebo reference="thigh_lr">
    <material>Gazebo/Grey</material>
  </gazebo>
  <gazebo reference="shin_lr">
    <material>Gazebo/Grey</material>
  </gazebo>
  <gazebo reference="shoe_lr">
    <material>Gazebo/Grey</material>
  </gazebo>
  <!-- Gazebo gravity setting -->
  <!-- <turnGravityOff>1</turnGravityOff> -->
  <gazebo>
    <plugin filename="libgazebo_ros_control.so" name="gazebo_ros_control">
      <robotNamespace>/worms/</robotNamespace>
    </plugin>
  </gazebo>
</robot>
